<?xml version="1.0" encoding="UTF-8"?>
<mujoco model="simple_robot">
  <!-- Options -->
  <option timestep="0.01" iterations="50" solver="Newton" tolerance="1e-10"/>
  
  <!-- Defaults -->
  <default>
    <default class="visual">
      <geom contype="0" conaffinity="0" group="1"/>
    </default>
    <default class="collision">
      <geom contype="1" conaffinity="1" group="0"/>
    </default>
    <default class="joint">
      <joint armature="0.01" damping="0.1" frictionloss="0.01"/>
    </default>
    <default class="actuator">
      <position ctrlrange="-1 1" kp="100"/>
    </default>
  </default>
  
  <!-- Assets -->
  <asset>
    <texture name="grid" type="2d" builtin="checker" rgb1="0.1 0.2 0.3" rgb2="0.2 0.3 0.4" width="512" height="512"/>
    <material name="grid" texture="grid" texrepeat="1 1" texuniform="true" reflectance="0.2"/>
    <material name="robot" rgba="0.7 0.7 0.7 1"/>
    <material name="target" rgba="0 1 0 0.5"/>
  </asset>
  
  <!-- World -->
  <worldbody>
    <!-- Ground plane -->
    <geom name="ground" type="plane" size="10 10 0.1" pos="0 0 0" quat="1 0 0 0" material="grid" class="collision"/>
    <geom name="ground_visual" type="plane" size="10 10 0.1" pos="0 0 0" quat="1 0 0 0" material="grid" class="visual"/>
    
    <!-- Robot base -->
    <body name="base" pos="0 0 0.1">
      <geom name="base_geom" type="cylinder" size="0.1 0.05" material="robot" class="collision"/>
      <geom name="base_visual" type="cylinder" size="0.1 0.05" material="robot" class="visual"/>
      
      <!-- Joint 1 -->
      <body name="link1" pos="0 0 0.05">
        <joint name="joint1" type="hinge" axis="0 0 1" pos="0 0 0" class="joint"/>
        <geom name="link1_geom" type="cylinder" size="0.05 0.1" pos="0 0 0.1" material="robot" class="collision"/>
        <geom name="link1_visual" type="cylinder" size="0.05 0.1" pos="0 0 0.1" material="robot" class="visual"/>
        
        <!-- Joint 2 -->
        <body name="link2" pos="0 0 0.2">
          <joint name="joint2" type="hinge" axis="0 1 0" pos="0 0 0" class="joint"/>
          <geom name="link2_geom" type="cylinder" size="0.05 0.1" pos="0 0 0.1" material="robot" class="collision"/>
          <geom name="link2_visual" type="cylinder" size="0.05 0.1" pos="0 0 0.1" material="robot" class="visual"/>
          
          <!-- Joint 3 -->
          <body name="link3" pos="0 0 0.2">
            <joint name="joint3" type="hinge" axis="0 1 0" pos="0 0 0" class="joint"/>
            <geom name="link3_geom" type="cylinder" size="0.05 0.1" pos="0 0 0.1" material="robot" class="collision"/>
            <geom name="link3_visual" type="cylinder" size="0.05 0.1" pos="0 0 0.1" material="robot" class="visual"/>
            
            <!-- End effector -->
            <body name="end_effector" pos="0 0 0.2">
              <geom name="end_effector_geom" type="sphere" size="0.02" material="robot" class="collision"/>
              <geom name="end_effector_visual" type="sphere" size="0.02" material="robot" class="visual"/>
            </body>
          </body>
        </body>
      </body>
    </body>
    
    <!-- Target -->
    <body name="target" pos="0.5 0.5 0.1" mocap="true">
      <geom name="target_geom" type="sphere" size="0.05" material="target" class="visual"/>
    </body>
  </worldbody>
  
  <!-- Actuators -->
  <actuator>
    <position name="actuator1" joint="joint1" class="actuator"/>
    <position name="actuator2" joint="joint2" class="actuator"/>
    <position name="actuator3" joint="joint3" class="actuator"/>
  </actuator>
  
  <!-- Sensors -->
  <sensor>
    <jointpos name="joint1_pos" joint="joint1"/>
    <jointpos name="joint2_pos" joint="joint2"/>
    <jointpos name="joint3_pos" joint="joint3"/>
    <jointvel name="joint1_vel" joint="joint1"/>
    <jointvel name="joint2_vel" joint="joint2"/>
    <jointvel name="joint3_vel" joint="joint3"/>
  </sensor>
  
  <!-- Keyframes -->
  <keyframe>
    <key name="home" qpos="0 0 0 0 0 0"/>
  </keyframe>
</mujoco> 